Workbook

Sheet G4- Attendance
C1: Section: | E1: Attendance & Effort Sheet | P1: P=Present
A2: Teacher Name: | E2: Computing, Creative Design and Innovation | P2: A=Absent
A3: School ID: | E3: Grade 4 | P3: L=Late
A4: School Name: | E4: Term 2 - 2024/2025
A5: Emirate/Area: | E5: 1. Student 'attendance' and 'effort' is part of the total of the School-Based mark. Please ensure that you record all attendance here.
A6: Council: | E6: 2. Consult your principal for late/absent policy
E7: Week 1 | G7: Week 2 | I7: Week 3 | K7: Effort | L7: Week 4 | N7: Week 5 | P7: Effort | Q7: Week 6 | S7: Week 7 | U7: Effort | V7: Week 8 | X7: Week 9 | Z7: Effort | AA7: Avg
B8: No | C8: Student # | D8: Student Name | E8: 45663 | G8: 45670 | I8: 45677 | K8: 10M | L8: 45684 | N8: 45691 | P8: 10M | Q8: 45698 | S8: 45705 | U8: 10M | V8: 45712 | X8: 45719 | Z8: 10M | AA8: Effort | AB8: #Present | AC8: #Late | AD8: #Absence | AE8: Tot Att | AF8: Attendance Mark (10) | AG8: Effort Mark (10) | AH8: Total Marks (20) | AI8: Comments
B9: 1 | C9: 1 | D9: Layla Abdulla | E9: NA | F9: NA | G9: P | H9: P | I9: P | J9: P | K9: 10 | L9: P | M9: P | N9: P | O9: P | P9: 10 | Q9: P | R9: P | S9: P | T9: P | U9: 10 | V9: P | W9: P | X9: P | Y9: P | Z9: 10 | AA9: =AVERAGE(K9,P9,U9,Z9) | AB9: =COUNTIF(G9:Z9,"P") | AC9: =COUNTIF(G9:Z9,"L") | AD9: =COUNTIF(G9:Z9,"A") | AE9: =AB9+AC9 | AF9: =AE9/16*10 | AG9: =AA9 | AH9: =AF9+AG9 | AI9: Excellent work and effort
B10: 2 | C10: 2 | D10: Salma | E10: NA | F10: NA | G10: P | H10: P | I10: P | J10: P | K10: 10 | L10: A | M10: A | N10: L | O10: P | P10: 10 | Q10: P | R10: P | S10: P | T10: P | U10: 10 | V10: P | W10: P | X10: P | Y10: P | Z10: 10 | AA10: =AVERAGE(K10,P10,U10,Z10) | AB10: =COUNTIF(G10:Z10,"P") | AC10: =COUNTIF(G10:Z10,"L") | AD10: =COUNTIF(G10:Z10,"A") | AE10: =AB10+AC10 | AF10: =AE10/16*10 | AG10: =AA10 | AH10: =AF10+AG10
B11: 3 | C11: 3 | D11: Fatima | E11: NA | F11: NA | G11: P | H11: P | I11: P | J11: A | K11: 5 | L11: A | M11: A | N11: P | O11: P | P11: 5 | Q11: a | R11: A | S11: P | T11: P | U11: 5 | V11: a | W11: A | X11: a | Y11: a | Z11: 5 | AA11: =AVERAGE(K11,P11,U11,Z11) | AB11: =COUNTIF(G11:Z11,"P") | AC11: =COUNTIF(G11:Z11,"L") | AD11: =COUNTIF(G11:Z11,"A") | AE11: =AB11+AC11 | AF11: =AE11/16*10 | AG11: =AA11 | AH11: =AF11+AG11
B12: 4 | E12: NA | F12: NA | K12: 0 | P12: 0 | U12: 0 | Z12: 0 | AA12: =AVERAGE(K12,P12,U12,Z12) | AB12: =COUNTIF(G12:Z12,"P") | AC12: =COUNTIF(G12:Z12,"L") | AD12: =COUNTIF(G12:Z12,"A") | AE12: =AB12+AC12 | AF12: =AE12/16*10 | AG12: =AA12 | AH12: =AF12+AG12
B13: 5 | E13: NA | F13: NA | K13: 0 | P13: 0 | U13: 0 | Z13: 0 | AA13: =AVERAGE(K13,P13,U13,Z13) | AB13: =COUNTIF(G13:Z13,"P") | AC13: =COUNTIF(G13:Z13,"L") | AD13: =COUNTIF(G13:Z13,"A") | AE13: =AB13+AC13 | AF13: =AE13/16*10 | AG13: =AA13 | AH13: =AF13+AG13
B14: 6 | E14: NA | F14: NA | K14: 0 | P14: 0 | U14: 0 | Z14: 0 | AA14: =AVERAGE(K14,P14,U14,Z14) | AB14: =COUNTIF(G14:Z14,"P") | AC14: =COUNTIF(G14:Z14,"L") | AD14: =COUNTIF(G14:Z14,"A") | AE14: =AB14+AC14 | AF14: =AE14/16*10 | AG14: =AA14 | AH14: =AF14+AG14
B15: 7 | E15: NA | F15: NA | K15: 0 | P15: 0 | U15: 0 | Z15: 0 | AA15: =AVERAGE(K15,P15,U15,Z15) | AB15: =COUNTIF(G15:Z15,"P") | AC15: =COUNTIF(G15:Z15,"L") | AD15: =COUNTIF(G15:Z15,"A") | AE15: =AB15+AC15 | AF15: =AE15/16*10 | AG15: =AA15 | AH15: =AF15+AG15
B16: 8 | E16: NA | F16: NA | K16: 0 | P16: 0 | U16: 0 | Z16: 0 | AA16: =AVERAGE(K16,P16,U16,Z16) | AB16: =COUNTIF(G16:Z16,"P") | AC16: =COUNTIF(G16:Z16,"L") | AD16: =COUNTIF(G16:Z16,"A") | AE16: =AB16+AC16 | AF16: =AE16/16*10 | AG16: =AA16 | AH16: =AF16+AG16
B17: 9 | E17: NA | F17: NA | K17: 0 | P17: 0 | U17: 0 | Z17: 0 | AA17: =AVERAGE(K17,P17,U17,Z17) | AB17: =COUNTIF(G17:Z17,"P") | AC17: =COUNTIF(G17:Z17,"L") | AD17: =COUNTIF(G17:Z17,"A") | AE17: =AB17+AC17 | AF17: =AE17/16*10 | AG17: =AA17 | AH17: =AF17+AG17
B18: 10 | E18: NA | F18: NA | K18: 0 | P18: 0 | U18: 0 | Z18: 0 | AA18: =AVERAGE(K18,P18,U18,Z18) | AB18: =COUNTIF(G18:Z18,"P") | AC18: =COUNTIF(G18:Z18,"L") | AD18: =COUNTIF(G18:Z18,"A") | AE18: =AB18+AC18 | AF18: =AE18/16*10 | AG18: =AA18 | AH18: =AF18+AG18
B19: 11 | E19: NA | F19: NA | K19: 0 | P19: 0 | U19: 0 | Z19: 0 | AA19: =AVERAGE(K19,P19,U19,Z19) | AB19: =COUNTIF(G19:Z19,"P") | AC19: =COUNTIF(G19:Z19,"L") | AD19: =COUNTIF(G19:Z19,"A") | AE19: =AB19+AC19 | AF19: =AE19/16*10 | AG19: =AA19 | AH19: =AF19+AG19
B20: 12 | E20: NA | F20: NA | K20: 0 | P20: 0 | U20: 0 | Z20: 0 | AA20: =AVERAGE(K20,P20,U20,Z20) | AB20: =COUNTIF(G20:Z20,"P") | AC20: =COUNTIF(G20:Z20,"L") | AD20: =COUNTIF(G20:Z20,"A") | AE20: =AB20+AC20 | AF20: =AE20/16*10 | AG20: =AA20 | AH20: =AF20+AG20
B21: 13 | E21: NA | F21: NA | K21: 0 | P21: 0 | U21: 0 | Z21: 0 | AA21: =AVERAGE(K21,P21,U21,Z21) | AB21: =COUNTIF(G21:Z21,"P") | AC21: =COUNTIF(G21:Z21,"L") | AD21: =COUNTIF(G21:Z21,"A") | AE21: =AB21+AC21 | AF21: =AE21/16*10 | AG21: =AA21 | AH21: =AF21+AG21
B22: 14 | E22: NA | F22: NA | K22: 0 | P22: 0 | U22: 0 | Z22: 0 | AA22: =AVERAGE(K22,P22,U22,Z22) | AB22: =COUNTIF(G22:Z22,"P") | AC22: =COUNTIF(G22:Z22,"L") | AD22: =COUNTIF(G22:Z22,"A") | AE22: =AB22+AC22 | AF22: =AE22/16*10 | AG22: =AA22 | AH22: =AF22+AG22
B23: 15 | E23: NA | F23: NA | K23: 0 | P23: 0 | U23: 0 | Z23: 0 | AA23: =AVERAGE(K23,P23,U23,Z23) | AB23: =COUNTIF(G23:Z23,"P") | AC23: =COUNTIF(G23:Z23,"L") | AD23: =COUNTIF(G23:Z23,"A") | AE23: =AB23+AC23 | AF23: =AE23/16*10 | AG23: =AA23 | AH23: =AF23+AG23
... B35: 27 | E35: NA | F35: NA | K35: 0 | P35: 0 | U35: 0 | Z35: 0 | AA35: =AVERAGE(K35,P35,U35,Z35) | AB35: =COUNTIF(G35:Z35,"P") | AC35: =COUNTIF(G35:Z35,"L") | AD35: =COUNTIF(G35:Z35,"A") | AE35: =AB35+AC35 | AF35: =AE35/16*10 | AG35: =AA35 | AH35: =AF35+AG35
B36: 28 | D36: Mariam | E36: NA | F36: NA | K36: 5 | L36: p | M36: p | N36: p | O36: p | P36: 5 | Q36: p | R36: p | S36: p | T36: p | U36: 5 | V36: a | W36: a | X36: a | Y36: a | Z36: 5 | AA36: =AVERAGE(K36,P36,U36,Z36) | AB36: =COUNTIF(G36:Z36,"P") | AC36: =COUNTIF(G36:Z36,"L") | AD36: =COUNTIF(G36:Z36,"A") | AE36: =AB36+AC36 | AF36: =AE36/16*10 | AG36: =AA36 | AH36: =AF36+AG36
B37: 29 | E37: NA | F37: NA | K37: 0 | P37: 0 | U37: 0 | Z37: 0 | AA37: =AVERAGE(K37,P37,U37,Z37) | AB37: =COUNTIF(G37:Z37,"P") | AC37: =COUNTIF(G37:Z37,"L") | AD37: =COUNTIF(G37:Z37,"A") | AE37: =AB37+AC37 | AF37: =AE37/16*10 | AG37: =AA37 | AH37: =AF37+AG37
B38: 30 | E38: NA | F38: NA | K38: 0 | P38: 0 | U38: 0 | Z38: 0 | AA38: =AVERAGE(K38,P38,U38,Z38) | AB38: =COUNTIF(G38:Z38,"P") | AC38: =COUNTIF(G38:Z38,"L") | AD38: =COUNTIF(G38:Z38,"A") | AE38: =AB38+AC38 | AF38: =AE38/16*10 | AG38: =AA38 | AH38: =AF38+AG38
B39: 31 | E39: NA | F39: NA | K39: 0 | P39: 0 | U39: 0 | Z39: 0 | AA39: =AVERAGE(K39,P39,U39,Z39) | AB39: =COUNTIF(G39:Z39,"P") | AC39: =COUNTIF(G39:Z39,"L") | AD39: =COUNTIF(G39:Z39,"A") | AE39: =AB39+AC39 | AF39: =AE39/16*10 | AG39: =AA39 | AH39: =AF39+AG39
B40: 32 | E40: NA | F40: NA | K40: 0 | P40: 0 | U40: 0 | Z40: 0 | AA40: =AVERAGE(K40,P40,U40,Z40) | AB40: =COUNTIF(G40:Z40,"P") | AC40: =COUNTIF(G40:Z40,"L") | AD40: =COUNTIF(G40:Z40,"A") | AE40: =AB40+AC40 | AF40: =AE40/16*10 | AG40: =AA40 | AH40: =AF40+AG40
B41: 33 | E41: NA | F41: NA | K41: 0 | P41: 0 | U41: 0 | Z41: 0 | AA41: =AVERAGE(K41,P41,U41,Z41) | AB41: =COUNTIF(G41:Z41,"P") | AC41: =COUNTIF(G41:Z41,"L") | AD41: =COUNTIF(G41:Z41,"A") | AE41: =AB41+AC41 | AF41: =AE41/16*10 | AG41: =AA41 | AH41: =AF41+AG41
B42: 34 | E42: NA | F42: NA | K42: 0 | P42: 0 | U42: 0 | Z42: 0 | AA42: =AVERAGE(K42,P42,U42,Z42) | AB42: =COUNTIF(G42:Z42,"P") | AC42: =COUNTIF(G42:Z42,"L") | AD42: =COUNTIF(G42:Z42,"A") | AE42: =AB42+AC42 | AF42: =AE42/16*10 | AG42: =AA42 | AH42: =AF42+AG42
B43: 35 | E43: NA | F43: NA | K43: 0 | P43: 0 | U43: 0 | Z43: 0 | AA43: =AVERAGE(K43,P43,U43,Z43) | AB43: =COUNTIF(G43:Z43,"P") | AC43: =COUNTIF(G43:Z43,"L") | AD43: =COUNTIF(G43:Z43,"A") | AE43: =AB43+AC43 | AF43: =AE43/16*10 | AG43: =AA43 | AH43: =AF43+AG43
B44: 36 | E44: NA | F44: NA | K44: 0 | P44: 0 | U44: 0 | Z44: 0 | AA44: =AVERAGE(K44,P44,U44,Z44) | AB44: =COUNTIF(G44:Z44,"P") | AC44: =COUNTIF(G44:Z44,"L") | AD44: =COUNTIF(G44:Z44,"A") | AE44: =AB44+AC44 | AF44: =AE44/16*10 | AG44: =AA44 | AH44: =AF44+AG44
B45: 37 | E45: NA | F45: NA | K45: 0 | P45: 0 | U45: 0 | Z45: 0 | AA45: =AVERAGE(K45,P45,U45,Z45) | AB45: =COUNTIF(G45:Z45,"P") | AC45: =COUNTIF(G45:Z45,"L") | AD45: =COUNTIF(G45:Z45,"A") | AE45: =AB45+AC45 | AF45: =AE45/16*10 | AG45: =AA45 | AH45: =AF45+AG45
B46: 38 | E46: NA | F46: NA | K46: 0 | P46: 0 | U46: 0 | Z46: 0 | AA46: =AVERAGE(K46,P46,U46,Z46) | AB46: =COUNTIF(G46:Z46,"P") | AC46: =COUNTIF(G46:Z46,"L") | AD46: =COUNTIF(G46:Z46,"A") | AE46: =AB46+AC46 | AF46: =AE46/16*10 | AG46: =AA46 | AH46: =AF46+AG46
B47: 39 | E47: NA | F47: NA | K47: 0 | P47: 0 | U47: 0 | Z47: 0 | AA47: =AVERAGE(K47,P47,U47,Z47) | AB47: =COUNTIF(G47:Z47,"P") | AC47: =COUNTIF(G47:Z47,"L") | AD47: =COUNTIF(G47:Z47,"A") | AE47: =AB47+AC47 | AF47: =AE47/16*10 | AG47: =AA47 | AH47: =AF47+AG47
B48: 40 | E48: NA | F48: NA | K48: 0 | P48: 0 | U48: 0 | Z48: 0 | AA48: =AVERAGE(K48,P48,U48,Z48) | AB48: =COUNTIF(G48:Z48,"P") | AC48: =COUNTIF(G48:Z48,"L") | AD48: =COUNTIF(G48:Z48,"A") | AE48: =AB48+AC48 | AF48: =AE48/16*10 | AG48: =AA48 | AH48: =AF48+AG48
... B58: 50 | E58: NA | F58: NA | K58: 0 | P58: 0 | U58: 0 | Z58: 0 | AA58: =AVERAGE(K58,P58,U58,Z58) | AB58: =COUNTIF(G58:Z58,"P") | AC58: =COUNTIF(G58:Z58,"L") | AD58: =COUNTIF(G58:Z58,"A") | AE58: =AB58+AC58 | AF58: =AE58/16*10 | AG58: =AA58 | AH58: =AF58+AG58

Sheet G4- Marks
C1: Section: | D1: ='G4- Attendance'!D1 | E1: Marks Recording Sheet
A2: Teacher Name: | D2: ='G4- Attendance'!D2 | E2: ='G4- Attendance'!E2
A3: School ID: | D3: ='G4- Attendance'!D3 | E3: ='G4- Attendance'!E3
A4: School Name: | D4: ='G4- Attendance'!D4 | E4: ='G4- Attendance'!E4
A5: Emirate/Area: | D5: ='G4- Attendance'!D5
A6: Council: | D6: ='G4- Attendance'!D6
E7: School-based Assessment (SB1) | F7: Attendance/ Effort | G7: School-based Total | H7: End of Term Total
B8: No | C8: Student # | D8: Student Name | E8: 80 marks | F8: 20 marks | G8: 100 marks | H8: 100 marks
B9: 1 | C9: ='G4- Attendance'!C9 | D9: ='G4- Attendance'!D9 | E9: 80 | F9: ='G4- Attendance'!AH9 | G9: =E9+F9 | H9: 99
B10: 2 | C10: ='G4- Attendance'!C10 | D10: ='G4- Attendance'!D10 | E10: 75 | F10: ='G4- Attendance'!AH10 | G10: =E10+F10 | H10: 77
B11: 3 | C11: ='G4- Attendance'!C11 | D11: ='G4- Attendance'!D11 | E11: 40 | F11: ='G4- Attendance'!AH11 | G11: =E11+F11 | H11: 55
B12: 4 | C12: ='G4- Attendance'!C12 | D12: ='G4- Attendance'!D12 | F12: ='G4- Attendance'!AH12 | G12: =E12+F12 | H12: 71
B13: 5 | C13: ='G4- Attendance'!C13 | D13: ='G4- Attendance'!D13 | F13: ='G4- Attendance'!AH13 | G13: =E13+F13 | H13: 78
B14: 6 | C14: ='G4- Attendance'!C14 | D14: ='G4- Attendance'!D14 | F14: ='G4- Attendance'!AH14 | G14: =E14+F14 | H14: 72
B15: 7 | C15: ='G4- Attendance'!C15 | D15: ='G4- Attendance'!D15 | F15: ='G4- Attendance'!AH15 | G15: =E15+F15 | H15: 94
B16: 8 | C16: ='G4- Attendance'!C16 | D16: ='G4- Attendance'!D16 | F16: ='G4- Attendance'!AH16 | G16: =E16+F16 | H16: 83
B17: 9 | C17: ='G4- Attendance'!C17 | D17: ='G4- Attendance'!D17 | F17: ='G4- Attendance'!AH17 | G17: =E17+F17 | H17: 78
B18: 10 | C18: ='G4- Attendance'!C18 | D18: ='G4- Attendance'!D18 | F18: ='G4- Attendance'!AH18 | G18: =E18+F18 | H18: 73
B19: 11 | C19: ='G4- Attendance'!C19 | D19: ='G4- Attendance'!D19 | F19: ='G4- Attendance'!AH19 | G19: =E19+F19 | H19: 96
B20: 12 | C20: ='G4- Attendance'!C20 | D20: ='G4- Attendance'!D20 | F20: ='G4- Attendance'!AH20 | G20: =E20+F20 | H20: 98
B21: 13 | C21: ='G4- Attendance'!C21 | D21: ='G4- Attendance'!D21 | F21: ='G4- Attendance'!AH21 | G21: =E21+F21 | H21: 97
B22: 14 | C22: ='G4- Attendance'!C22 | D22: ='G4- Attendance'!D22 | F22: ='G4- Attendance'!AH22 | G22: =E22+F22 | H22: 71
B23: 15 | C23: ='G4- Attendance'!C23 | D23: Mariam | E23: 20 | F23: 10 | G23: =E23+F23 | H23: 75
B24: 16 | C24: ='G4- Attendance'!C24 | D24: ='G4- Attendance'!D24 | F24: ='G4- Attendance'!AH24 | G24: =E24+F24 | H24: 82
B25: 17 | C25: ='G4- Attendance'!C25 | D25: ='G4- Attendance'!D25 | F25: ='G4- Attendance'!AH25 | G25: =E25+F25 | H25: 87
B26: 18 | C26: ='G4- Attendance'!C26 | D26: ='G4- Attendance'!D26 | F26: ='G4- Attendance'!AH26 | G26: =E26+F26 | H26: 99
B27: 19 | C27: ='G4- Attendance'!C27 | D27: ='G4- Attendance'!D27 | E27: 40 | F27: ='G4- Attendance'!AH27 | G27: =E27+F27 | H27: 77
B28: 20 | C28: ='G4- Attendance'!C28 | D28: ='G4- Attendance'!D28 | F28: ='G4- Attendance'!AH28 | G28: =E28+F28 | H28: 55
B29: 21 | C29: ='G4- Attendance'!C29 | D29: ='G4- Attendance'!D29 | F29: ='G4- Attendance'!AH29 | G29: =E29+F29 | H29: 87
B30: 22 | C30: ='G4- Attendance'!C30 | D30: ='G4- Attendance'!D30 | F30: ='G4- Attendance'!AH30 | G30: =E30+F30 | H30: 80
B31: 23 | C31: ='G4- Attendance'!C31 | D31: ='G4- Attendance'!D31 | F31: ='G4- Attendance'!AH31 | G31: =E31+F31 | H31: 80
B32: 24 | C32: ='G4- Attendance'!C32 | D32: ='G4- Attendance'!D32 | F32: ='G4- Attendance'!AH32 | G32: =E32+F32 | H32: 97
B33: 25 | C33: ='G4- Attendance'!C33 | D33: ='G4- Attendance'!D33 | F33: ='G4- Attendance'!AH33 | G33: =E33+F33 | H33: 71
B34: 26 | C34: ='G4- Attendance'!C34 | D34: ='G4- Attendance'!D34 | F34: ='G4- Attendance'!AH34 | G34: =E34+F34 | H34: 75
B35: 27 | C35: ='G4- Attendance'!C35 | D35: ='G4- Attendance'!D35 | F35: ='G4- Attendance'!AH35 | G35: =E35+F35 | H35: 74
B36: 28 | C36: ='G4- Attendance'!C36 | D36: ='G4- Attendance'!D36 | E36: 40 | F36: ='G4- Attendance'!AH36 | G36: =E36+F36 | H36: 80
B37: 29 | C37: ='G4- Attendance'!C37 | D37: ='G4- Attendance'!D37 | F37: ='G4- Attendance'!AH37 | G37: =E37+F37 | H37: 87
B38: 30 | C38: ='G4- Attendance'!C38 | D38: ='G4- Attendance'!D38 | F38: ='G4- Attendance'!AH38 | G38: =E38+F38 | H38: 80
B39: 31 | C39: ='G4- Attendance'!C39 | D39: ='G4- Attendance'!D39 | F39: ='G4- Attendance'!AH39 | G39: =E39+F39 | H39: 92
B40: 32 | C40: ='G4- Attendance'!C40 | D40: ='G4- Attendance'!D40 | F40: ='G4- Attendance'!AH40 | G40: =E40+F40 | H40: 75
...

Sheet 4 - Attendance
C1: Section: | D1: 4 | E1: Attendance & Effort Sheet | P1: P=Present
A2: Teacher Name: | E2: Computing, Creative Design and Innovation | P2: A=Absent
A3: School ID: | E3: Grade 4 | P3: L=Late
A4: School Name: | E4: Term 2 - 2024/2025
A5: Emirate/Area: | E5: 1. Student 'attendance' and 'effort' is part of the total of the School-Based mark. Please ensure that you record all attendance here.
A6: Council: | E6: 2. Consult your principal for late/absent policy
E7: Week 1 | G7: Week 2 | I7: Week 3 | K7: Effort | L7: Week 4 | N7: Week 5 | P7: Effort | Q7: Week 6 | S7: Week 7 | U7: Effort | V7: Week 8 | X7: Week 9 | Z7: Effort | AA7: Avg
B8: No | C8: Student # | D8: Student Name | E8: 45663 | G8: 45670 | I8: 45677 | K8: 10M | L8: 45684 | N8: 45691 | P8: 10M | Q8: 45698 | S8: 45705 | U8: 10M | V8: 45712 | X8: 45719 | Z8: 10M | AA8: Effort | AB8: #Present | AC8: #Late | AD8: #Absence | AE8: Tot Att | AF8: Attendance Mark (10) | AG8: Effort Mark (10) | AH8: Total Marks (20) | AI8: Comments
B9: 1 | C9: 1 | D9: الدماني منصور عجيل الشين الجحافي | E9: NA | F9: NA | G9: P | H9: P | I9: P | J9: P | K9: 10 | L9: P | M9: P | N9: P | O9: P | P9: 10 | Q9: P | R9: P | S9: P | T9: P | U9: 10 | V9: P | W9: P | X9: P | Y9: P | Z9: 10 | AA9: =AVERAGE(K9,P9,U9,Z9) | AB9: =COUNTIF(G9:Z9,"P") | AC9: =COUNTIF(G9:Z9,"L") | AD9: =COUNTIF(G9:Z9,"A") | AE9: =AB9+AC9 | AF9: =AE9/16*10 | AG9: =AA9 | AH9: 19 | AI9: Excellent work and effort
B10: 2 | C10: 2 | D10: بسملة خمليش | E10: NA | F10: NA | G10: P | H10: P | I10: P | J10: P | K10: 10 | L10: A | M10: A | N10: L | O10: P | P10: 10 | Q10: P | R10: P | S10: P | T10: P | U10: 10 | V10: P | W10: P | X10: P | Y10: P | Z10: 10 | AA10: =AVERAGE(K10,P10,U10,Z10) | AB10: =COUNTIF(G10:Z10,"P") | AC10: =COUNTIF(G10:Z10,"L") | AD10: =COUNTIF(G10:Z10,"A") | AE10: =AB10+AC10 | AF10: =AE10/16*10 | AG10: =AA10 | AH10: 20
B11: 3 | C11: 3 | D11: حصه صالح سالم البرك العامري | E11: NA | F11: NA | G11: P | H11: P | I11: P | J11: A | K11: 5 | L11: A | M11: A | N11: P | O11: P | P11: 5 | Q11: a | R11: A | S11: P | T11: P | U11: 5 | V11: a | W11: A | X11: a | Y11: a | Z11: 5 | AA11: =AVERAGE(K11,P11,U11,Z11) | AB11: =COUNTIF(G11:Z11,"P") | AC11: =COUNTIF(G11:Z11,"L") | AD11: =COUNTIF(G11:Z11,"A") | AE11: =AB11+AC11 | AF11: =AE11/16*10 | AG11: =AA11 | AH11: 20
B12: 4 | C12: 4 | D12: حمدان محمد سعيد سالمين بن اسحاق | E12: NA | F12: NA | K12: 0 | P12: 0 | U12: 0 | Z12: 0 | AA12: =AVERAGE(K12,P12,U12,Z12) | AB12: =COUNTIF(G12:Z12,"P") | AC12: =COUNTIF(G12:Z12,"L") | AD12: =COUNTIF(G12:Z12,"A") | AE12: =AB12+AC12 | AF12: =AE12/16*10 | AG12: =AA12 | AH12: 20
B13: 5 | C13: 5 | D13: حياة ناصر جمعه راشد الكعبي | E13: NA | F13: NA | K13: 0 | P13: 0 | U13: 0 | Z13: 0 | AA13: =AVERAGE(K13,P13,U13,Z13) | AB13: =COUNTIF(G13:Z13,"P") | AC13: =COUNTIF(G13:Z13,"L") | AD13: =COUNTIF(G13:Z13,"A") | AE13: =AB13+AC13 | AF13: =AE13/16*10 | AG13: =AA13 | AH13: 19
B14: 6 | C14: 6 | D14: سلمان سالم احمد سالم المنصوري | E14: NA | F14: NA | K14: 0 | P14: 0 | U14: 0 | Z14: 0 | AA14: =AVERAGE(K14,P14,U14,Z14) | AB14: =COUNTIF(G14:Z14,"P") | AC14: =COUNTIF(G14:Z14,"L") | AD14: =COUNTIF(G14:Z14,"A") | AE14: =AB14+AC14 | AF14: =AE14/16*10 | AG14: =AA14 | AH14: 19
B15: 7 | C15: 7 | D15: شيخة هداف رضوان عيضة المنهالي | E15: NA | F15: NA | K15: 0 | P15: 0 | U15: 0 | Z15: 0 | AA15: =AVERAGE(K15,P15,U15,Z15) | AB15: =COUNTIF(G15:Z15,"P") | AC15: =COUNTIF(G15:Z15,"L") | AD15: =COUNTIF(G15:Z15,"A") | AE15: =AB15+AC15 | AF15: =AE15/16*10 | AG15: =AA15 | AH15: 20
B16: 8 | C16: 8 | D16: عائشه منصور محمد احمد الحضرمى | E16: NA | F16: NA | K16: 0 | P16: 0 | U16: 0 | Z16: 0 | AA16: =AVERAGE(K16,P16,U16,Z16) | AB16: =COUNTIF(G16:Z16,"P") | AC16: =COUNTIF(G16:Z16,"L") | AD16: =COUNTIF(G16:Z16,"A") | AE16: =AB16+AC16 | AF16: =AE16/16*10 | AG16: =AA16 | AH16: 18
B17: 9 | C17: 9 | D17: عبدالله بدر حسين عيسى | E17: NA | F17: NA | K17: 0 | P17: 0 | U17: 0 | Z17: 0 | AA17: =AVERAGE(K17,P17,U17,Z17) | AB17: =COUNTIF(G17:Z17,"P") | AC17: =COUNTIF(G17:Z17,"L") | AD17: =COUNTIF(G17:Z17,"A") | AE17: =AB17+AC17 | AF17: =AE17/16*10 | AG17: =AA17 | AH17: 18
B18: 10 | C18: 10 | D18: عبدالله نوح قاسم جان محمد البلوشى | E18: NA | F18: NA | K18: 0 | P18: 0 | U18: 0 | Z18: 0 | AA18: =AVERAGE(K18,P18,U18,Z18) | AB18: =COUNTIF(G18:Z18,"P") | AC18: =COUNTIF(G18:Z18,"L") | AD18: =COUNTIF(G18:Z18,"A") | AE18: =AB18+AC18 | AF18: =AE18/16*10 | AG18: =AA18 | AH18: 19
B19: 11 | C19: 11 | D19: فاطمه محمد سعيد سالم الشامسي | E19: NA | F19: NA | K19: 0 | P19: 0 | U19: 0 | Z19: 0 | AA19: =AVERAGE(K19,P19,U19,Z19) | AB19: =COUNTIF(G19:Z19,"P") | AC19: =COUNTIF(G19:Z19,"L") | AD19: =COUNTIF(G19:Z19,"A") | AE19: =AB19+AC19 | AF19: =AE19/16*10 | AG19: =AA19 | AH19: 20
B20: 12 | C20: 12 | D20: مثايل خالد ناصر راشد الساعدي | E20: NA | F20: NA | K20: 0 | P20: 0 | U20: 0 | Z20: 0 | AA20: =AVERAGE(K20,P20,U20,Z20) | AB20: =COUNTIF(G20:Z20,"P") | AC20: =COUNTIF(G20:Z20,"L") | AD20: =COUNTIF(G20:Z20,"A") | AE20: =AB20+AC20 | AF20: =AE20/16*10 | AG20: =AA20 | AH20: 19
B21: 13 | C21: 13 | D21: محمد خالد سالم سلطان الكعبى | E21: NA | F21: NA | K21: 0 | P21: 0 | U21: 0 | Z21: 0 | AA21: =AVERAGE(K21,P21,U21,Z21) | AB21: =COUNTIF(G21:Z21,"P") | AC21: =COUNTIF(G21:Z21,"L") | AD21: =COUNTIF(G21:Z21,"A") | AE21: =AB21+AC21 | AF21: =AE21/16*10 | AG21: =AA21 | AH21: 18
B22: 14 | C22: 14 | D22: محمد صقر محمد بجير العامري | E22: NA | F22: NA | K22: 0 | P22: 0 | U22: 0 | Z22: 0 | AA22: =AVERAGE(K22,P22,U22,Z22) | AB22: =COUNTIF(G22:Z22,"P") | AC22: =COUNTIF(G22:Z22,"L") | AD22: =COUNTIF(G22:Z22,"A") | AE22: =AB22+AC22 | AF22: =AE22/16*10 | AG22: =AA22 | AH22: 20
B23: 15 | C23: 15 | D23: محمد عوض هادي فلاح الاحبابي | E23: NA | F23: NA | K23: 0 | P23: 0 | U23: 0 | Z23: 0 | AA23: =AVERAGE(K23,P23,U23,Z23) | AB23: =COUNTIF(G23:Z23,"P") | AC23: =COUNTIF(G23:Z23,"L") | AD23: =COUNTIF(G23:Z23,"A") | AE23: =AB23+AC23 | AF23: =AE23/16*10 | AG23: =AA23 | AH23: 20
... B25: 17 | C25: 17 | D25: ناصر صالح سليمان مبارك العامري | E25: NA | F25: NA | K25: 0 | P25: 0 | U25: 0 | Z25: 0 | AA25: =AVERAGE(K25,P25,U25,Z25) | AB25: =COUNTIF(G25:Z25,"P") | AC25: =COUNTIF(G25:Z25,"L") | AD25: =COUNTIF(G25:Z25,"A") | AE25: =AB25+AC25 | AF25: =AE25/16*10 | AG25: =AA25 | AH25: 20
B26: 18 | E26: NA | F26: NA | K26: 0 | P26: 0 | U26: 0 | Z26: 0 | AA26: =AVERAGE(K26,P26,U26,Z26) | AB26: =COUNTIF(G26:Z26,"P") | AC26: =COUNTIF(G26:Z26,"L") | AD26: =COUNTIF(G26:Z26,"A") | AE26: =AB26+AC26 | AF26: =AE26/16*10 | AG26: =AA26
B27: 19 | E27: NA | F27: NA | K27: 0 | P27: 0 | U27: 0 | Z27: 0 | AA27: =AVERAGE(K27,P27,U27,Z27) | AB27: =COUNTIF(G27:Z27,"P") | AC27: =COUNTIF(G27:Z27,"L") | AD27: =COUNTIF(G27:Z27,"A") | AE27: =AB27+AC27 | AF27: =AE27/16*10 | AG27: =AA27
B28: 20 | E28: NA | F28: NA | K28: 0 | P28: 0 | U28: 0 | Z28: 0 | AA28: =AVERAGE(K28,P28,U28,Z28) | AB28: =COUNTIF(G28:Z28,"P") | AC28: =COUNTIF(G28:Z28,"L") | AD28: =COUNTIF(G28:Z28,"A") | AE28: =AB28+AC28 | AF28: =AE28/16*10 | AG28: =AA28
B29: 21 | E29: NA | F29: NA | K29: 0 | P29: 0 | U29: 0 | Z29: 0 | AA29: =AVERAGE(K29,P29,U29,Z29) | AB29: =COUNTIF(G29:Z29,"P") | AC29: =COUNTIF(G29:Z29,"L") | AD29: =COUNTIF(G29:Z29,"A") | AE29: =AB29+AC29 | AF29: =AE29/16*10 | AG29: =AA29
B30: 22 | E30: NA | F30: NA | K30: 0 | P30: 0 | U30: 0 | Z30: 0 | AA30: =AVERAGE(K30,P30,U30,Z30) | AB30: =COUNTIF(G30:Z30,"P") | AC30: =COUNTIF(G30:Z30,"L") | AD30: =COUNTIF(G30:Z30,"A") | AE30: =AB30+AC30 | AF30: =AE30/16*10 | AG30: =AA30
B31: 23 | E31: NA | F31: NA | K31: 0 | P31: 0 | U31: 0 | Z31: 0 | AA31: =AVERAGE(K31,P31,U31,Z31) | AB31: =COUNTIF(G31:Z31,"P") | AC31: =COUNTIF(G31:Z31,"L") | AD31: =COUNTIF(G31:Z31,"A") | AE31: =AB31+AC31 | AF31: =AE31/16*10 | AG31: =AA31
B32: 24 | E32: NA | F32: NA | K32: 0 | P32: 0 | U32: 0 | Z32: 0 | AA32: =AVERAGE(K32,P32,U32,Z32) | AB32: =COUNTIF(G32:Z32,"P") | AC32: =COUNTIF(G32:Z32,"L") | AD32: =COUNTIF(G32:Z32,"A") | AE32: =AB32+AC32 | AF32: =AE32/16*10 | AG32: =AA32
B33: 25 | E33: NA | F33: NA | K33: 0 | P33: 0 | U33: 0 | Z33: 0 | AA33: =AVERAGE(K33,P33,U33,Z33) | AB33: =COUNTIF(G33:Z33,"P") | AC33: =COUNTIF(G33:Z33,"L") | AD33: =COUNTIF(G33:Z33,"A") | AE33: =AB33+AC33 | AF33: =AE33/16*10 | AG33: =AA33
B34: 26 | E34: NA | F34: NA | K34: 0 | P34: 0 | U34: 0 | Z34: 0 | AA34: =AVERAGE(K34,P34,U34,Z34) | AB34: =COUNTIF(G34:Z34,"P") | AC34: =COUNTIF(G34:Z34,"L") | AD34: =COUNTIF(G34:Z34,"A") | AE34: =AB34+AC34 | AF34: =AE34/16*10 | AG34: =AA34
B35: 27 | E35: NA | F35: NA | K35: 0 | P35: 0 | U35: 0 | Z35: 0 | AA35: =AVERAGE(K35,P35,U35,Z35) | AB35: =COUNTIF(G35:Z35,"P") | AC35: =COUNTIF(G35:Z35,"L") | AD35: =COUNTIF(G35:Z35,"A") | AE35: =AB35+AC35 | AF35: =AE35/16*10 | AG35: =AA35
B36: 28 | E36: NA | F36: NA | K36: 5 | L36: p | M36: p | N36: p | O36: p | P36: 5 | Q36: p | R36: p | S36: p | T36: p | U36: 5 | V36: a | W36: a | X36: a | Y36: a | Z36: 5 | AA36: =AVERAGE(K36,P36,U36,Z36) | AB36: =COUNTIF(G36:Z36,"P") | AC36: =COUNTIF(G36:Z36,"L") | AD36: =COUNTIF(G36:Z36,"A") | AE36: =AB36+AC36 | AF36: =AE36/16*10 | AG36: =AA36
B37: 29 | E37: NA | F37: NA | K37: 0 | P37: 0 | U37: 0 | Z37: 0 | AA37: =AVERAGE(K37,P37,U37,Z37) | AB37: =COUNTIF(G37:Z37,"P") | AC37: =COUNTIF(G37:Z37,"L") | AD37: =COUNTIF(G37:Z37,"A") | AE37: =AB37+AC37 | AF37: =AE37/16*10 | AG37: =AA37
B38: 30 | E38: NA | F38: NA | K38: 0 | P38: 0 | U38: 0 | Z38: 0 | AA38: =AVERAGE(K38,P38,U38,Z38) | AB38: =COUNTIF(G38:Z38,"P") | AC38: =COUNTIF(G38:Z38,"L") | AD38: =COUNTIF(G38:Z38,"A") | AE38: =AB38+AC38 | AF38: =AE38/16*10 | AG38: =AA38
B39: 31 | E39: NA | F39: NA | K39: 0 | P39: 0 | U39: 0 | Z39: 0 | AA39: =AVERAGE(K39,P39,U39,Z39) | AB39: =COUNTIF(G39:Z39,"P") | AC39: =COUNTIF(G39:Z39,"L") | AD39: =COUNTIF(G39:Z39,"A") | AE39: =AB39+AC39 | AF39: =AE39/16*10 | AG39: =AA39
B40: 32 | E40: NA | F40: NA | K40: 0 | P40: 0 | U40: 0 | Z40: 0 | AA40: =AVERAGE(K40,P40,U40,Z40) | AB40: =COUNTIF(G40:Z40,"P") | AC40: =COUNTIF(G40:Z40,"L") | AD40: =COUNTIF(G40:Z40,"A") | AE40: =AB40+AC40 | AF40: =AE40/16*10 | AG40: =AA40
B41: 33 | E41: NA | F41: NA | K41: 0 | P41: 0 | U41: 0 | Z41: 0 | AA41: =AVERAGE(K41,P41,U41,Z41) | AB41: =COUNTIF(G41:Z41,"P") | AC41: =COUNTIF(G41:Z41,"L") | AD41: =COUNTIF(G41:Z41,"A") | AE41: =AB41+AC41 | AF41: =AE41/16*10 | AG41: =AA41
...

Sheet 4 - Marks
C1: Section: | D1: 4 | E1: Marks Recording Sheet
A2: Teacher Name: | D2: ='G4- Attendance'!D2 | E2: ='G4- Attendance'!E2
A3: School ID: | D3: ='G4- Attendance'!D3 | E3: ='G4- Attendance'!E3
A4: School Name: | D4: ='G4- Attendance'!D4 | E4: ='G4- Attendance'!E4
A5: Emirate/Area: | D5: ='G4- Attendance'!D5
A6: Council: | D6: ='G4- Attendance'!D6
E7: School-based Assessment (SB1) | F7: Attendance/ Effort | G7: School-based Total | H7: End of Term Total
B8: No | C8: Student # | D8: Student Name | E8: 80 marks | F8: 20 marks | G8: 100 marks | H8: 100 marks
B9: 1 | C9: 1 | D9: الدماني منصور عجيل الشين الجحافي | E9: 33 | F9: 19 | G9: 52 | H9: 99
B10: 2 | C10: 2 | D10: بسملة خمليش | E10: 40 | F10: 20 | G10: 60 | H10: 77
B11: 3 | C11: 3 | D11: حصه صالح سالم البرك العامري | E11: 74 | F11: 20 | G11: 94 | H11: 55
B12: 4 | C12: 4 | D12: حمدان محمد سعيد سالمين بن اسحاق | E12: 73 | F12: 20 | G12: 93 | H12: 71
B13: 5 | C13: 5 | D13: حياة ناصر جمعه راشد الكعبي | E13: 64 | F13: 19 | G13: 83 | H13: 78
B14: 6 | C14: 6 | D14: سلمان سالم احمد سالم المنصوري | E14: 38 | F14: 19 | G14: 57 | H14: 72
B15: 7 | C15: 7 | D15: شيخة هداف رضوان عيضة المنهالي | E15: 49 | F15: 20 | G15: 69 | H15: 94
B16: 8 | C16: 8 | D16: عائشه منصور محمد احمد الحضرمى | E16: 63 | F16: 18 | G16: 81 | H16: 83
B17: 9 | C17: 9 | D17: عبدالله بدر حسين عيسى | E17: 68 | F17: 18 | G17: 86 | H17: 78
B18: 10 | C18: 10 | D18: عبدالله نوح قاسم جان محمد البلوشى | E18: 71 | F18: 19 | G18: 90 | H18: 73
B19: 11 | C19: 11 | D19: فاطمه محمد سعيد سالم الشامسي | E19: 76 | F19: 20 | G19: 96 | H19: 96
B20: 12 | C20: 12 | D20: مثايل خالد ناصر راشد الساعدي | E20: 71 | F20: 19 | G20: 90 | H20: 98
... B25: 17 | C25: 17 | D25: ناصر صالح سليمان مبارك العامري | E25: 29 | F25: 20 | G25: 49 | H25: 87
H27: 88

Sheet 4A - Attendance
C1: Section: | D1: 4A | E1: Attendance & Effort Sheet | P1: P=Present
A2: Teacher Name: | E2: Computing, Creative Design and Innovation | P2: A=Absent
A3: School ID: | E3: Grade 4 | P3: L=Late
A4: School Name: | E4: Term 2 - 2024/2025
A5: Emirate/Area: | E5: 1. Student 'attendance' and 'effort' is part of the total of the School-Based mark. Please ensure that you record all attendance here.
A6: Council: | E6: 2. Consult your principal for late/absent policy
E7: Week 1 | G7: Week 2 | I7: Week 3 | K7: Effort | L7: Week 4 | N7: Week 5 | P7: Effort | Q7: Week 6 | S7: Week 7 | U7: Effort | V7: Week 8 | X7: Week 9 | Z7: Effort | AA7: Avg
B8: No | C8: Student # | D8: Student Name | E8: 45663 | G8: 45670 | I8: 45677 | K8: 10M | L8: 45684 | N8: 45691 | P8: 10M | Q8: 45698 | S8: 45705 | U8: 10M | V8: 45712 | X8: 45719 | Z8: 10M | AA8: Effort | AB8: #Present | AC8: #Late | AD8: #Absence | AE8: Tot Att | AF8: Attendance Mark (10) | AG8: Effort Mark (10) | AH8: Total Marks (20) | AI8: Comments
B9: 1 | C9: 1 | D9: بيان عبدالله صالح مبارك المصعبي | E9: NA | F9: NA | G9: P | H9: P | I9: P | J9: P | K9: 10 | L9: P | M9: P | N9: P | O9: P | P9: 10 | Q9: P | R9: P | S9: P | T9: P | U9: 10 | V9: P | W9: P | X9: P | Y9: P | Z9: 10 | AA9: =AVERAGE(K9,P9,U9,Z9) | AB9: =COUNTIF(G9:Z9,"P") | AC9: =COUNTIF(G9:Z9,"L") | AD9: =COUNTIF(G9:Z9,"A") | AE9: =AB9+AC9 | AF9: =AE9/16*10 | AG9: =AA9 | AH9: 18 | AI9: Excellent work and effort
B10: 2 | C10: 2 | D10: جورى حمد احمد عبدالله البلوشي | E10: NA | F10: NA | G10: P | H10: P | I10: P | J10: P | K10: 10 | L10: A | M10: A | N10: L | O10: P | P10: 10 | Q10: P | R10: P | S10: P | T10: P | U10: 10 | V10: P | W10: P | X10: P | Y10: P | Z10: 10 | AA10: =AVERAGE(K10,P10,U10,Z10) | AB10: =COUNTIF(G10:Z10,"P") | AC10: =COUNTIF(G10:Z10,"L") | AD10: =COUNTIF(G10:Z10,"A") | AE10: =AB10+AC10 | AF10: =AE10/16*10 | AG10: =AA10 | AH10: 18
B11: 3 | C11: 3 | D11: حامد فارس محمد سيف الكعبي | E11: NA | F11: NA | G11: P | H11: P | I11: P | J11: A | K11: 5 | L11: A | M11: A | N11: P | O11: P | P11: 5 | Q11: a | R11: A | S11: P | T11: P | U11: 5 | V11: a | W11: A | X11: a | Y11: a | Z11: 5 | AA11: =AVERAGE(K11,P11,U11,Z11) | AB11: =COUNTIF(G11:Z11,"P") | AC11: =COUNTIF(G11:Z11,"L") | AD11: =COUNTIF(G11:Z11,"A") | AE11: =AB11+AC11 | AF11: =AE11/16*10 | AG11: =AA11 | AH11: 20
B12: 4 | C12: 4 | D12: حلا حمد مبارك بن شيخه المرى | E12: NA | F12: NA | K12: 0 | P12: 0 | U12: 0 | Z12: 0 | AA12: =AVERAGE(K12,P12,U12,Z12) | AB12: =COUNTIF(G12:Z12,"P") | AC12: =COUNTIF(G12:Z12,"L") | AD12: =COUNTIF(G12:Z12,"A") | AE12: =AB12+AC12 | AF12: =AE12/16*10 | AG12: =AA12 | AH12: 18
B13: 5 | C13: 5 | D13: حمد عبدالله سعيد سبيت الكعبي | E13: NA | F13: NA | K13: 0 | P13: 0 | U13: 0 | Z13: 0 | AA13: =AVERAGE(K13,P13,U13,Z13) | AB13: =COUNTIF(G13:Z13,"P") | AC13: =COUNTIF(G13:Z13,"L") | AD13: =COUNTIF(G13:Z13,"A") | AE13: =AB13+AC13 | AF13: =AE13/16*10 | AG13: =AA13 | AH13: 20
B14: 6 | C14: 6 | D14: حمدان عبدالله محمد وهيب احمد | E14: NA | F14: NA | K14: 0 | P14: 0 | U14: 0 | Z14: 0 | AA14: =AVERAGE(K14,P14,U14,Z14) | AB14: =COUNTIF(G14:Z14,"P") | AC14: =COUNTIF(G14:Z14,"L") | AD14: =COUNTIF(G14:Z14,"A") | AE14: =AB14+AC14 | AF14: =AE14/16*10 | AG14: =AA14 | AH14: 19
B15: 7 | C15: 7 | D15: خالد مسفر ناصر سعود المنصوري | E15: NA | F15: NA | K15: 0 | P15: 0 | U15: 0 | Z15: 0 | AA15: =AVERAGE(K15,P15,U15,Z15) | AB15: =COUNTIF(G15:Z15,"P") | AC15: =COUNTIF(G15:Z15,"L") | AD15: =COUNTIF(G15:Z15,"A") | AE15: =AB15+AC15 | AF15: =AE15/16*10 | AG15: =AA15 | AH15: 18
B16: 8 | C16: 8 | D16: دلال عوض عايض معيض العتيبي | E16: NA | F16: NA | K16: 0 | P16: 0 | U16: 0 | Z16: 0 | AA16: =AVERAGE(K16,P16,U16,Z16) | AB16: =COUNTIF(G16:Z16,"P") | AC16: =COUNTIF(G16:Z16,"L") | AD16: =COUNTIF(G16:Z16,"A") | AE16: =AB16+AC16 | AF16: =AE16/16*10 | AG16: =AA16 | AH16: 18
B17: 9 | C17: 9 | D17: راشد عوض ضاحى مبارك الحسانى | E17: NA | F17: NA | K17: 0 | P17: 0 | U17: 0 | Z17: 0 | AA17: =AVERAGE(K17,P17,U17,Z17) | AB17: =COUNTIF(G17:Z17,"P") | AC17: =COUNTIF(G17:Z17,"L") | AD17: =COUNTIF(G17:Z17,"A") | AE17: =AB17+AC17 | AF17: =AE17/16*10 | AG17: =AA17 | AH17: 20
B18: 10 | C18: 10 | D18: روضة خميس عبدالله سالم الشامسي | E18: NA | F18: NA | K18: 0 | P18: 0 | U18: 0 | Z18: 0 | AA18: =AVERAGE(K18,P18,U18,Z18) | AB18: =COUNTIF(G18:Z18,"P") | AC18: =COUNTIF(G18:Z18,"L") | AD18: =COUNTIF(G18:Z18,"A") | AE18: =AB18+AC18 | AF18: =AE18/16*10 | AG18: =AA18 | AH18: 18
B19: 11 | C19: 11 | D19: شما عيظة مبارك عيظة العامري | E19: NA | F19: NA | K19: 0 | P19: 0 | U19: 0 | Z19: 0 | AA19: =AVERAGE(K19,P19,U19,Z19) | AB19: =COUNTIF(G19:Z19,"P") | AC19: =COUNTIF(G19:Z19,"L") | AD19: =COUNTIF(G19:Z19,"A") | AE19: =AB19+AC19 | AF19: =AE19/16*10 | AG19: =AA19 | AH19: 18
B20: 12 | C20: 12 | D20: شماء جابر على محمد | E20: NA | F20: NA | K20: 0 | P20: 0 | U20: 0 | Z20: 0 | AA20: =AVERAGE(K20,P20,U20,Z20) | AB20: =COUNTIF(G20:Z20,"P") | AC20: =COUNTIF(G20:Z20,"L") | AD20: =COUNTIF(G20:Z20,"A") | AE20: =AB20+AC20 | AF20: =AE20/16*10 | AG20: =AA20 | AH20: 19
B21: 13 | C21: 13 | D21: شيخه بنت سالم بن محمد بن على المقباليه | E21: NA | F21: NA | K21: 0 | P21: 0 | U21: 0 | Z21: 0 | AA21: =AVERAGE(K21,P21,U21,Z21) | AB21: =COUNTIF(G21:Z21,"P") | AC21: =COUNTIF(G21:Z21,"L") | AD21: =COUNTIF(G21:Z21,"A") | AE21: =AB21+AC21 | AF21: =AE21/16*10 | AG21: =AA21 | AH21: 18
B22: 14 | C22: 14 | D22: ظبيه سعيد خليفه محمد الرواحيه | E22: NA | F22: NA | K22: 0 | P22: 0 | U22: 0 | Z22: 0 | AA22: =AVERAGE(K22,P22,U22,Z22) | AB22: =COUNTIF(G22:Z22,"P") | AC22: =COUNTIF(G22:Z22,"L") | AD22: =COUNTIF(G22:Z22,"A") | AE22: =AB22+AC22 | AF22: =AE22/16*10 | AG22: =AA22 | AH22: 19
B23: 15 | C23: 15 | D23: عبدالله سالم عبدالله سويدان المقبالى | E23: NA | F23: NA | K23: 0 | P23: 0 | U23: 0 | Z23: 0 | AA23: =AVERAGE(K23,P23,U23,Z23) | AB23: =COUNTIF(G23:Z23,"P") | AC23: =COUNTIF(G23:Z23,"L") | AD23: =COUNTIF(G23:Z23,"A") | AE23: =AB23+AC23 | AF23: =AE23/16*10 | AG23: =AA23 | AH23: 19
... B35: 27 | C35: 27 | D35: مهره جمعه سالم سعيد الكعبي | E35: NA | F35: NA | K35: 0 | P35: 0 | U35: 0 | Z35: 0 | AA35: =AVERAGE(K35,P35,U35,Z35) | AB35: =COUNTIF(G35:Z35,"P") | AC35: =COUNTIF(G35:Z35,"L") | AD35: =COUNTIF(G35:Z35,"A") | AE35: =AB35+AC35 | AF35: =AE35/16*10 | AG35: =AA35 | AH35: 19
B36: 28 | C36: 28 | D36: مهره سعيد عبيد محمد الكعبي | E36: NA | F36: NA | K36: 5 | L36: p | M36: p | N36: p | O36: p | P36: 5 | Q36: p | R36: p | S36: p | T36: p | U36: 5 | V36: a | W36: a | X36: a | Y36: a | Z36: 5 | AA36: =AVERAGE(K36,P36,U36,Z36) | AB36: =COUNTIF(G36:Z36,"P") | AC36: =COUNTIF(G36:Z36,"L") | AD36: =COUNTIF(G36:Z36,"A") | AE36: =AB36+AC36 | AF36: =AE36/16*10 | AG36: =AA36 | AH36: 19
B37: 29 | C37: 29 | D37: ميره سعيد عبيد محمد الكعبي | E37: NA | F37: NA | K37: 0 | P37: 0 | U37: 0 | Z37: 0 | AA37: =AVERAGE(K37,P37,U37,Z37) | AB37: =COUNTIF(G37:Z37,"P") | AC37: =COUNTIF(G37:Z37,"L") | AD37: =COUNTIF(G37:Z37,"A") | AE37: =AB37+AC37 | AF37: =AE37/16*10 | AG37: =AA37 | AH37: 18
B38: 30 | E38: NA | F38: NA | K38: 0 | P38: 0 | U38: 0 | Z38: 0 | AA38: =AVERAGE(K38,P38,U38,Z38) | AB38: =COUNTIF(G38:Z38,"P") | AC38: =COUNTIF(G38:Z38,"L") | AD38: =COUNTIF(G38:Z38,"A") | AE38: =AB38+AC38 | AF38: =AE38/16*10 | AG38: =AA38
B39: 31 | E39: NA | F39: NA | K39: 0 | P39: 0 | U39: 0 | Z39: 0 | AA39: =AVERAGE(K39,P39,U39,Z39) | AB39: =COUNTIF(G39:Z39,"P") | AC39: =COUNTIF(G39:Z39,"L") | AD39: =COUNTIF(G39:Z39,"A") | AE39: =AB39+AC39 | AF39: =AE39/16*10 | AG39: =AA39
B40: 32 | E40: NA | F40: NA | K40: 0 | P40: 0 | U40: 0 | Z40: 0 | AA40: =AVERAGE(K40,P40,U40,Z40) | AB40: =COUNTIF(G40:Z40,"P") | AC40: =COUNTIF(G40:Z40,"L") | AD40: =COUNTIF(G40:Z40,"A") | AE40: =AB40+AC40 | AF40: =AE40/16*10 | AG40: =AA40
B41: 33 | E41: NA | F41: NA | K41: 0 | P41: 0 | U41: 0 | Z41: 0 | AA41: =AVERAGE(K41,P41,U41,Z41) | AB41: =COUNTIF(G41:Z41,"P") | AC41: =COUNTIF(G41:Z41,"L") | AD41: =COUNTIF(G41:Z41,"A") | AE41: =AB41+AC41 | AF41: =AE41/16*10 | AG41: =AA41
B42: 34 | E42: NA | F42: NA | K42: 0 | P42: 0 | U42: 0 | Z42: 0 | AA42: =AVERAGE(K42,P42,U42,Z42) | AB42: =COUNTIF(G42:Z42,"P") | AC42: =COUNTIF(G42:Z42,"L") | AD42: =COUNTIF(G42:Z42,"A") | AE42: =AB42+AC42 | AF42: =AE42/16*10 | AG42: =AA42
B43: 35 | E43: NA | F43: NA | K43: 0 | P43: 0 | U43: 0 | Z43: 0 | AA43: =AVERAGE(K43,P43,U43,Z43) | AB43: =COUNTIF(G43:Z43,"P") | AC43: =COUNTIF(G43:Z43,"L") | AD43: =COUNTIF(G43:Z43,"A") | AE43: =AB43+AC43 | AF43: =AE43/16*10 | AG43: =AA43
B44: 36 | E44: NA | F44: NA | K44: 0 | P44: 0 | U44: 0 | Z44: 0 | AA44: =AVERAGE(K44,P44,U44,Z44) | AB44: =COUNTIF(G44:Z44,"P") | AC44: =COUNTIF(G44:Z44,"L") | AD44: =COUNTIF(G44:Z44,"A") | AE44: =AB44+AC44 | AF44: =AE44/16*10 | AG44: =AA44
B45: 37 | E45: NA | F45: NA | K45: 0 | P45: 0 | U45: 0 | Z45: 0 | AA45: =AVERAGE(K45,P45,U45,Z45) | AB45: =COUNTIF(G45:Z45,"P") | AC45: =COUNTIF(G45:Z45,"L") | AD45: =COUNTIF(G45:Z45,"A") | AE45: =AB45+AC45 | AF45: =AE45/16*10 | AG45: =AA45
B46: 38 | E46: NA | F46: NA | K46: 0 | P46: 0 | U46: 0 | Z46: 0 | AA46: =AVERAGE(K46,P46,U46,Z46) | AB46: =COUNTIF(G46:Z46,"P") | AC46: =COUNTIF(G46:Z46,"L") | AD46: =COUNTIF(G46:Z46,"A") | AE46: =AB46+AC46 | AF46: =AE46/16*10 | AG46: =AA46
B47: 39 | E47: NA | F47: NA | K47: 0 | P47: 0 | U47: 0 | Z47: 0 | AA47: =AVERAGE(K47,P47,U47,Z47) | AB47: =COUNTIF(G47:Z47,"P") | AC47: =COUNTIF(G47:Z47,"L") | AD47: =COUNTIF(G47:Z47,"A") | AE47: =AB47+AC47 | AF47: =AE47/16*10 | AG47: =AA47
B48: 40 | E48: NA | F48: NA | K48: 0 | P48: 0 | U48: 0 | Z48: 0 | AA48: =AVERAGE(K48,P48,U48,Z48) | AB48: =COUNTIF(G48:Z48,"P") | AC48: =COUNTIF(G48:Z48,"L") | AD48: =COUNTIF(G48:Z48,"A") | AE48: =AB48+AC48 | AF48: =AE48/16*10 | AG48: =AA48
B49: 41 | E49: NA | F49: NA | K49: 0 | P49: 0 | U49: 0 | Z49: 0 | AA49: =AVERAGE(K49,P49,U49,Z49) | AB49: =COUNTIF(G49:Z49,"P") | AC49: =COUNTIF(G49:Z49,"L") | AD49: =COUNTIF(G49:Z49,"A") | AE49: =AB49+AC49 | AF49: =AE49/16*10 | AG49: =AA49
... B58: 50 | E58: NA | F58: NA | K58: 0 | P58: 0 | U58: 0 | Z58: 0 | AA58: =AVERAGE(K58,P58,U58,Z58) | AB58: =COUNTIF(G58:Z58,"P") | AC58: =COUNTIF(G58:Z58,"L") | AD58: =COUNTIF(G58:Z58,"A") | AE58: =AB58+AC58 | AF58: =AE58/16*10 | AG58: =AA58

Sheet 4A - Marks
C1: Section: | D1: 4A | E1: Marks Recording Sheet
A2: Teacher Name: | D2: ='G4- Attendance'!D2 | E2: ='G4- Attendance'!E2
A3: School ID: | D3: ='G4- Attendance'!D3 | E3: ='G4- Attendance'!E3
A4: School Name: | D4: ='G4- Attendance'!D4 | E4: ='G4- Attendance'!E4
A5: Emirate/Area: | D5: ='G4- Attendance'!D5
A6: Council: | D6: ='G4- Attendance'!D6
E7: School-based Assessment (SB1) | F7: Attendance/ Effort | G7: School-based Total | H7: End of Term Total
B8: No | C8: Student # | D8: Student Name | E8: 80 marks | F8: 20 marks | G8: 100 marks | H8: 100 marks
B9: 1 | C9: 1 | D9: بيان عبدالله صالح مبارك المصعبي | E9: 70 | F9: 18 | G9: 88 | H9: 99
B10: 2 | C10: 2 | D10: جورى حمد احمد عبدالله البلوشي | E10: 71 | F10: 18 | G10: 89 | H10: 77
B11: 3 | C11: 3 | D11: حامد فارس محمد سيف الكعبي | E11: 67 | F11: 20 | G11: 87 | H11: 55
B12: 4 | C12: 4 | D12: حلا حمد مبارك بن شيخه المرى | E12: 70 | F12: 18 | G12: 88 | H12: 87
B13: 5 | C13: 5 | D13: حمد عبدالله سعيد سبيت الكعبي | E13: 72 | F13: 20 | G13: 92 | H13: 80
B14: 6 | C14: 6 | D14: حمدان عبدالله محمد وهيب احمد | E14: 65 | F14: 19 | G14: 84 | H14: 80
B15: 7 | C15: 7 | D15: خالد مسفر ناصر سعود المنصوري | E15: 70 | F15: 18 | G15: 88 | H15: 97
B16: 8 | C16: 8 | D16: دلال عوض عايض معيض العتيبي | E16: 69 | F16: 18 | G16: 87 | H16: 71
B17: 9 | C17: 9 | D17: راشد عوض ضاحى مبارك الحسانى | E17: 67 | F17: 20 | G17: 87 | H17: 75
B18: 10 | C18: 10 | D18: روضة خميس عبدالله سالم الشامسي | E18: 68 | F18: 18 | G18: 86 | H18: 74
B19: 11 | C19: 11 | D19: شما عيظة مبارك عيظة العامري | E19: 68 | F19: 18 | G19: 86 | H19: 80
B20: 12 | C20: 12 | D20: شماء جابر على محمد | E20: 70 | F20: 19 | G20: 89 | H20: 87
... B37: 29 | C37: 29 | D37: ميره سعيد عبيد محمد الكعبي | E37: 68 | F37: 18 | G37: 86 | H37: 80

Sheet 4B - Attendance
C1: Section: | D1: 4B | E1: Attendance & Effort Sheet | P1: P=Present
A2: Teacher Name: | E2: Computing, Creative Design and Innovation | P2: A=Absent
A3: School ID: | E3: Grade 4 | P3: L=Late
A4: School Name: | E4: Term 2 - 2024/2025
A5: Emirate/Area: | E5: 1. Student 'attendance' and 'effort' is part of the total of the School-Based mark. Please ensure that you record all attendance here.
A6: Council: | E6: 2. Consult your principal for late/absent policy
E7: Week 1 | G7: Week 2 | I7: Week 3 | K7: Effort | L7: Week 4 | N7: Week 5 | P7: Effort | Q7: Week 6 | S7: Week 7 | U7: Effort | V7: Week 8 | X7: Week 9 | Z7: Effort | AA7: Avg
B8: No | C8: Student # | D8: Student Name | E8: 45663 | G8: 45670 | I8: 45677 | K8: 10M | L8: 45684 | N8: 45691 | P8: 10M | Q8: 45698 | S8: 45705 | U8: 10M | V8: 45712 | X8: 45719 | Z8: 10M | AA8: Effort | AB8: #Present | AC8: #Late | AD8: #Absence | AE8: Tot Att | AF8: Attendance Mark (10) | AG8: Effort Mark (10) | AH8: Total Marks (20) | AI8: Comments
B9: 1 | C9: 1 | D9: احمد عبدالله علي سيف المزيني | E9: NA | F9: NA | G9: P | H9: P | I9: P | J9: P | K9: 10 | L9: P | M9: P | N9: P | O9: P | P9: 10 | Q9: P | R9: P | S9: P | T9: P | U9: 10 | V9: P | W9: P | X9: P | Y9: P | Z9: 10 | AA9: =AVERAGE(K9,P9,U9,Z9) | AB9: =COUNTIF(G9:Z9,"P") | AC9: =COUNTIF(G9:Z9,"L") | AD9: =COUNTIF(G9:Z9,"A") | AE9: =AB9+AC9 | AF9: =AE9/16*10 | AG9: =AA9 | AH9: 18 | AI9: Excellent work and effort
B10: 2 | C10: 2 | D10: جمعه مطر ضحى جمعه الظاهري | E10: NA | F10: NA | G10: P | H10: P | I10: P | J10: P | K10: 10 | L10: A | M10: A | N10: L | O10: P | P10: 10 | Q10: P | R10: P | S10: P | T10: P | U10: 10 | V10: P | W10: P | X10: P | Y10: P | Z10: 10 | AA10: =AVERAGE(K10,P10,U10,Z10) | AB10: =COUNTIF(G10:Z10,"P") | AC10: =COUNTIF(G10:Z10,"L") | AD10: =COUNTIF(G10:Z10,"A") | AE10: =AB10+AC10 | AF10: =AE10/16*10 | AG10: =AA10 | AH10: 18
B11: 3 | C11: 3 | D11: حسن صالح محمد عبدالله البريكي | E11: NA | F11: NA | G11: P | H11: P | I11: P | J11: A | K11: 5 | L11: A | M11: A | N11: P | O11: P | P11: 5 | Q11: a | R11: A | S11: P | T11: P | U11: 5 | V11: a | W11: A | X11: a | Y11: a | Z11: 5 | AA11: =AVERAGE(K11,P11,U11,Z11) | AB11: =COUNTIF(G11:Z11,"P") | AC11: =COUNTIF(G11:Z11,"L") | AD11: =COUNTIF(G11:Z11,"A") | AE11: =AB11+AC11 | AF11: =AE11/16*10 | AG11: =AA11 | AH11: 18
B12: 4 | C12: 4 | D12: حمدان محسن قادر بخش لال محمد احمد البلوشي | E12: NA | F12: NA | K12: 0 | P12: 0 | U12: 0 | Z12: 0 | AA12: =AVERAGE(K12,P12,U12,Z12) | AB12: =COUNTIF(G12:Z12,"P") | AC12: =COUNTIF(G12:Z12,"L") | AD12: =COUNTIF(G12:Z12,"A") | AE12: =AB12+AC12 | AF12: =AE12/16*10 | AG12: =AA12 | AH12: 18
B13: 5 | C13: 5 | D13: حميد حمد راشد محمد الكلباني | E13: NA | F13: NA | K13: 0 | P13: 0 | U13: 0 | Z13: 0 | AA13: =AVERAGE(K13,P13,U13,Z13) | AB13: =COUNTIF(G13:Z13,"P") | AC13: =COUNTIF(G13:Z13,"L") | AD13: =COUNTIF(G13:Z13,"A") | AE13: =AB13+AC13 | AF13: =AE13/16*10 | AG13: =AA13 | AH13: 20
B14: 6 | C14: 6 | D14: خالد هلال عبدالله بن محمد الشامسى | E14: NA | F14: NA | K14: 0 | P14: 0 | U14: 0 | Z14: 0 | AA14: =AVERAGE(K14,P14,U14,Z14) | AB14: =COUNTIF(G14:Z14,"P") | AC14: =COUNTIF(G14:Z14,"L") | AD14: =COUNTIF(G14:Z14,"A") | AE14: =AB14+AC14 | AF14: =AE14/16*10 | AG14: =AA14 | AH14: 19
B15: 7 | C15: 7 | D15: رحمه حمدان محمد ناجى احمد | E15: NA | F15: NA | K15: 0 | P15: 0 | U15: 0 | Z15: 0 | AA15: =AVERAGE(K15,P15,U15,Z15) | AB15: =COUNTIF(G15:Z15,"P") | AC15: =COUNTIF(G15:Z15,"L") | AD15: =COUNTIF(G15:Z15,"A") | AE15: =AB15+AC15 | AF15: =AE15/16*10 | AG15: =AA15 | AH15: 18
B16: 8 | C16: 8 | D16: روضة راضي مبخوت عبدالله | E16: NA | F16: NA | K16: 0 | P16: 0 | U16: 0 | Z16: 0 | AA16: =AVERAGE(K16,P16,U16,Z16) | AB16: =COUNTIF(G16:Z16,"P") | AC16: =COUNTIF(G16:Z16,"L") | AD16: =COUNTIF(G16:Z16,"A") | AE16: =AB16+AC16 | AF16: =AE16/16*10 | AG16: =AA16 | AH16: 19
B17: 9 | C17: 9 | D17: زايد حمدان محمد عبدالله المهيري | E17: NA | F17: NA | K17: 0 | P17: 0 | U17: 0 | Z17: 0 | AA17: =AVERAGE(K17,P17,U17,Z17) | AB17: =COUNTIF(G17:Z17,"P") | AC17: =COUNTIF(G17:Z17,"L") | AD17: =COUNTIF(G17:Z17,"A") | AE17: =AB17+AC17 | AF17: =AE17/16*10 | AG17: =AA17 | AH17: 19
B18: 10 | C18: 10 | D18: سلامه محسن احمد محسن عبدالله الحارثي | E18: NA | F18: NA | K18: 0 | P18: 0 | U18: 0 | Z18: 0 | AA18: =AVERAGE(K18,P18,U18,Z18) | AB18: =COUNTIF(G18:Z18,"P") | AC18: =COUNTIF(G18:Z18,"L") | AD18: =COUNTIF(G18:Z18,"A") | AE18: =AB18+AC18 | AF18: =AE18/16*10 | AG18: =AA18 | AH18: 20
B19: 11 | C19: 11 | D19: سيف جلال سالم البادي | E19: NA | F19: NA | K19: 0 | P19: 0 | U19: 0 | Z19: 0 | AA19: =AVERAGE(K19,P19,U19,Z19) | AB19: =COUNTIF(G19:Z19,"P") | AC19: =COUNTIF(G19:Z19,"L") | AD19: =COUNTIF(G19:Z19,"A") | AE19: =AB19+AC19 | AF19: =AE19/16*10 | AG19: =AA19 | AH19: 20
B20: 12 | C20: 12 | D20: سيف علي سعيد عمير الظاهري | E20: NA | F20: NA | K20: 0 | P20: 0 | U20: 0 | Z20: 0 | AA20: =AVERAGE(K20,P20,U20,Z20) | AB20: =COUNTIF(G20:Z20,"P") | AC20: =COUNTIF(G20:Z20,"L") | AD20: =COUNTIF(G20:Z20,"A") | AE20: =AB20+AC20 | AF20: =AE20/16*10 | AG20: =AA20 | AH20: 18
B21: 13 | C21: 13 | D21: صالح حمد صالح مبارك المشيعى | E21: NA | F21: NA | K21: 0 | P21: 0 | U21: 0 | Z21: 0 | AA21: =AVERAGE(K21,P21,U21,Z21) | AB21: =COUNTIF(G21:Z21,"P") | AC21: =COUNTIF(G21:Z21,"L") | AD21: =COUNTIF(G21:Z21,"A") | AE21: =AB21+AC21 | AF21: =AE21/16*10 | AG21: =AA21 | AH21: 19
B22: 14 | C22: 14 | D22: عايشه سالم علي سيف الخييلي | E22: NA | F22: NA | K22: 0 | P22: 0 | U22: 0 | Z22: 0 | AA22: =AVERAGE(K22,P22,U22,Z22) | AB22: =COUNTIF(G22:Z22,"P") | AC22: =COUNTIF(G22:Z22,"L") | AD22: =COUNTIF(G22:Z22,"A") | AE22: =AB22+AC22 | AF22: =AE22/16*10 | AG22: =AA22 | AH22: 18
B23: 15 | C23: 15 | D23: عبدالله على سالم مسعود الظاهري | E23: NA | F23: NA | K23: 0 | P23: 0 | U23: 0 | Z23: 0 | AA23: =AVERAGE(K23,P23,U23,Z23) | AB23: =COUNTIF(G23:Z23,"P") | AC23: =COUNTIF(G23:Z23,"L") | AD23: =COUNTIF(G23:Z23,"A") | AE23: =AB23+AC23 | AF23: =AE23/16*10 | AG23: =AA23 | AH23: 20
... B34: 26 | C34: 26 | D34: وديمه خليل هادى سعيد الأحبابي | E34: NA | F34: NA | K34: 0 | P34: 0 | U34: 0 | Z34: 0 | AA34: =AVERAGE(K34,P34,U34,Z34) | AB34: =COUNTIF(G34:Z34,"P") | AC34: =COUNTIF(G34:Z34,"L") | AD34: =COUNTIF(G34:Z34,"A") | AE34: =AB34+AC34 | AF34: =AE34/16*10 | AG34: =AA34 | AH34: 18
B35: 27 | E35: NA | F35: NA | K35: 0 | P35: 0 | U35: 0 | Z35: 0 | AA35: =AVERAGE(K35,P35,U35,Z35) | AB35: =COUNTIF(G35:Z35,"P") | AC35: =COUNTIF(G35:Z35,"L") | AD35: =COUNTIF(G35:Z35,"A") | AE35: =AB35+AC35 | AF35: =AE35/16*10 | AG35: =AA35
B36: 28 | E36: NA | F36: NA | K36: 5 | L36: p | M36: p | N36: p | O36: p | P36: 5 | Q36: p | R36: p | S36: p | T36: p | U36: 5 | V36: a | W36: a | X36: a | Y36: a | Z36: 5 | AA36: =AVERAGE(K36,P36,U36,Z36) | AB36: =COUNTIF(G36:Z36,"P") | AC36: =COUNTIF(G36:Z36,"L") | AD36: =COUNTIF(G36:Z36,"A") | AE36: =AB36+AC36 | AF36: =AE36/16*10 | AG36: =AA36
B37: 29 | E37: NA | F37: NA | K37: 0 | P37: 0 | U37: 0 | Z37: 0 | AA37: =AVERAGE(K37,P37,U37,Z37) | AB37: =COUNTIF(G37:Z37,"P") | AC37: =COUNTIF(G37:Z37,"L") | AD37: =COUNTIF(G37:Z37,"A") | AE37: =AB37+AC37 | AF37: =AE37/16*10 | AG37: =AA37
B38: 30 | E38: NA | F38: NA | K38: 0 | P38: 0 | U38: 0 | Z38: 0 | AA38: =AVERAGE(K38,P38,U38,Z38) | AB38: =COUNTIF(G38:Z38,"P") | AC38: =COUNTIF(G38:Z38,"L") | AD38: =COUNTIF(G38:Z38,"A") | AE38: =AB38+AC38 | AF38: =AE38/16*10 | AG38: =AA38
B39: 31 | E39: NA | F39: NA | K39: 0 | P39: 0 | U39: 0 | Z39: 0 | AA39: =AVERAGE(K39,P39,U39,Z39) | AB39: =COUNTIF(G39:Z39,"P") | AC39: =COUNTIF(G39:Z39,"L") | AD39: =COUNTIF(G39:Z39,"A") | AE39: =AB39+AC39 | AF39: =AE39/16*10 | AG39: =AA39
B40: 32 | E40: NA | F40: NA | K40: 0 | P40: 0 | U40: 0 | Z40: 0 | AA40: =AVERAGE(K40,P40,U40,Z40) | AB40: =COUNTIF(G40:Z40,"P") | AC40: =COUNTIF(G40:Z40,"L") | AD40: =COUNTIF(G40:Z40,"A") | AE40: =AB40+AC40 | AF40: =AE40/16*10 | AG40: =AA40
B41: 33 | E41: NA | F41: NA | K41: 0 | P41: 0 | U41: 0 | Z41: 0 | AA41: =AVERAGE(K41,P41,U41,Z41) | AB41: =COUNTIF(G41:Z41,"P") | AC41: =COUNTIF(G41:Z41,"L") | AD41: =COUNTIF(G41:Z41,"A") | AE41: =AB41+AC41 | AF41: =AE41/16*10 | AG41: =AA41
B42: 34 | E42: NA | F42: NA | K42: 0 | P42: 0 | U42: 0 | Z42: 0 | AA42: =AVERAGE(K42,P42,U42,Z42) | AB42: =COUNTIF(G42:Z42,"P") | AC42: =COUNTIF(G42:Z42,"L") | AD42: =COUNTIF(G42:Z42,"A") | AE42: =AB42+AC42 | AF42: =AE42/16*10 | AG42: =AA42
B43: 35 | E43: NA | F43: NA | K43: 0 | P43: 0 | U43: 0 | Z43: 0 | AA43: =AVERAGE(K43,P43,U43,Z43) | AB43: =COUNTIF(G43:Z43,"P") | AC43: =COUNTIF(G43:Z43,"L") | AD43: =COUNTIF(G43:Z43,"A") | AE43: =AB43+AC43 | AF43: =AE43/16*10 | AG43: =AA43
B44: 36 | E44: NA | F44: NA | K44: 0 | P44: 0 | U44: 0 | Z44: 0 | AA44: =AVERAGE(K44,P44,U44,Z44) | AB44: =COUNTIF(G44:Z44,"P") | AC44: =COUNTIF(G44:Z44,"L") | AD44: =COUNTIF(G44:Z44,"A") | AE44: =AB44+AC44 | AF44: =AE44/16*10 | AG44: =AA44
B45: 37 | E45: NA | F45: NA | K45: 0 | P45: 0 | U45: 0 | Z45: 0 | AA45: =AVERAGE(K45,P45,U45,Z45) | AB45: =COUNTIF(G45:Z45,"P") | AC45: =COUNTIF(G45:Z45,"L") | AD45: =COUNTIF(G45:Z45,"A") | AE45: =AB45+AC45 | AF45: =AE45/16*10 | AG45: =AA45
B46: 38 | E46: NA | F46: NA | K46: 0 | P46: 0 | U46: 0 | Z46: 0 | AA46: =AVERAGE(K46,P46,U46,Z46) | AB46: =COUNTIF(G46:Z46,"P") | AC46: =COUNTIF(G46:Z46,"L") | AD46: =COUNTIF(G46:Z46,"A") | AE46: =AB46+AC46 | AF46: =AE46/16*10 | AG46: =AA46
B47: 39 | E47: NA | F47: NA | K47: 0 | P47: 0 | U47: 0 | Z47: 0 | AA47: =AVERAGE(K47,P47,U47,Z47) | AB47: =COUNTIF(G47:Z47,"P") | AC47: =COUNTIF(G47:Z47,"L") | AD47: =COUNTIF(G47:Z47,"A") | AE47: =AB47+AC47 | AF47: =AE47/16*10 | AG47: =AA47
B48: 40 | E48: NA | F48: NA | K48: 0 | P48: 0 | U48: 0 | Z48: 0 | AA48: =AVERAGE(K48,P48,U48,Z48) | AB48: =COUNTIF(G48:Z48,"P") | AC48: =COUNTIF(G48:Z48,"L") | AD48: =COUNTIF(G48:Z48,"A") | AE48: =AB48+AC48 | AF48: =AE48/16*10 | AG48: =AA48
... B58: 50 | E58: NA | F58: NA | K58: 0 | P58: 0 | U58: 0 | Z58: 0 | AA58: =AVERAGE(K58,P58,U58,Z58) | AB58: =COUNTIF(G58:Z58,"P") | AC58: =COUNTIF(G58:Z58,"L") | AD58: =COUNTIF(G58:Z58,"A") | AE58: =AB58+AC58 | AF58: =AE58/16*10 | AG58: =AA58

Sheet 4B - Marks
C1: Section: | D1: 4B | E1: Marks Recording Sheet
A2: Teacher Name: | D2: ='G4- Attendance'!D2 | E2: ='G4- Attendance'!E2
A3: School ID: | D3: ='G4- Attendance'!D3 | E3: ='G4- Attendance'!E3
A4: School Name: | D4: ='G4- Attendance'!D4 | E4: ='G4- Attendance'!E4
A5: Emirate/Area: | D5: ='G4- Attendance'!D5
A6: Council: | D6: ='G4- Attendance'!D6
E7: School-based Assessment (SB1) | F7: Attendance/ Effort | G7: School-based Total | H7: End of Term Total
B8: No | C8: Student # | D8: Student Name | E8: 80 marks | F8: 20 marks | G8: 100 marks | H8: 100 marks
B9: 1 | C9: 1 | D9: احمد عبدالله علي سيف المزيني | E9: 80 | F9: 18 | G9: 98 | H9: 99
B10: 2 | C10: 2 | D10: جمعه مطر ضحى جمعه الظاهري | E10: 80 | F10: 18 | G10: 98 | H10: 77
B11: 3 | C11: 3 | D11: حسن صالح محمد عبدالله البريكي | E11: 80 | F11: 18 | G11: 98 | H11: 55
B12: 4 | C12: 4 | D12: حمدان محسن قادر بخش لال محمد احمد البلوشي | E12: 72 | F12: 18 | G12: 90 | H12: 92
B13: 5 | C13: 5 | D13: حميد حمد راشد محمد الكلباني | E13: 74 | F13: 20 | G13: 94 | H13: 93
B14: 6 | C14: 6 | D14: خالد هلال عبدالله بن محمد الشامسى | E14: 74 | F14: 19 | G14: 93 | H14: 92
B15: 7 | C15: 7 | D15: رحمه حمدان محمد ناجى احمد | E15: 70 | F15: 18 | G15: 88 | H15: 88
B16: 8 | C16: 8 | D16: روضة راضي مبخوت عبدالله | E16: 76 | F16: 19 | G16: 95 | H16: 94
B17: 9 | C17: 9 | D17: زايد حمدان محمد عبدالله المهيري | E17: 77 | F17: 19 | G17: 96 | H17: 87
B18: 10 | C18: 10 | D18: سلامه محسن احمد محسن عبدالله الحارثي | E18: 80 | F18: 20 | G18: 100 | H18: 92
B19: 11 | C19: 11 | D19: سيف جلال سالم البادي | E19: 68 | F19: 20 | G19: 88 | H19: 86
B20: 12 | C20: 12 | D20: سيف علي سعيد عمير الظاهري | E20: 66 | F20: 18 | G20: 84 | H20: 86
... B34: 26 | C34: 26 | D34: وديمه خليل هادى سعيد الأحبابي | E34: 79 | F34: 18 | G34: 97 | H34: 90

Sheet 4C - Attendance
C1: Section: | D1: 4C | E1: Attendance & Effort Sheet | P1: P=Present
A2: Teacher Name: | E2: Computing, Creative Design and Innovation | P2: A=Absent
A3: School ID: | E3: Grade 4 | P3: L=Late
A4: School Name: | E4: Term 2 - 2024/2025
A5: Emirate/Area: | E5: 1. Student 'attendance' and 'effort' is part of the total of the School-Based mark. Please ensure that you record all attendance here.
A6: Council: | E6: 2. Consult your principal for late/absent policy
E7: Week 1 | G7: Week 2 | I7: Week 3 | K7: Effort | L7: Week 4 | N7: Week 5 | P7: Effort | Q7: Week 6 | S7: Week 7 | U7: Effort | V7: Week 8 | X7: Week 9 | Z7: Effort | AA7: Avg
B8: No | C8: Student # | D8: Student Name | E8: 45663 | G8: 45670 | I8: 45677 | K8: 10M | L8: 45684 | N8: 45691 | P8: 10M | Q8: 45698 | S8: 45705 | U8: 10M | V8: 45712 | X8: 45719 | Z8: 10M | AA8: Effort | AB8: #Present | AC8: #Late | AD8: #Absence | AE8: Tot Att | AF8: Attendance Mark (10) | AG8: Effort Mark (10) | AH8: Total Marks (20) | AI8: Comments
B9: 1 | C9: 1 | D9: حصه صالح سالم البرك العامري | E9: NA | F9: NA | G9: P | H9: P | I9: P | J9: P | K9: 10 | L9: P | M9: P | N9: P | O9: P | P9: 10 | Q9: P | R9: P | S9: P | T9: P | U9: 10 | V9: P | W9: P | X9: P | Y9: P | Z9: 10 | AA9: =AVERAGE(K9,P9,U9,Z9) | AB9: =COUNTIF(G9:Z9,"P") | AC9: =COUNTIF(G9:Z9,"L") | AD9: =COUNTIF(G9:Z9,"A") | AE9: =AB9+AC9 | AF9: =AE9/16*10 | AG9: =AA9 | AH9: 18 | AI9: Excellent work and effort
B10: 2 | C10: 2 | D10: حصه عوض يسلم عوض الصيعري | E10: NA | F10: NA | G10: P | H10: P | I10: P | J10: P | K10: 10 | L10: A | M10: A | N10: L | O10: P | P10: 10 | Q10: P | R10: P | S10: P | T10: P | U10: 10 | V10: P | W10: P | X10: P | Y10: P | Z10: 10 | AA10: =AVERAGE(K10,P10,U10,Z10) | AB10: =COUNTIF(G10:Z10,"P") | AC10: =COUNTIF(G10:Z10,"L") | AD10: =COUNTIF(G10:Z10,"A") | AE10: =AB10+AC10 | AF10: =AE10/16*10 | AG10: =AA10 | AH10: 18
B11: 3 | C11: 3 | D11: حمد ابراهيم على محمد المستكاء | E11: NA | F11: NA | G11: P | H11: P | I11: P | J11: A | K11: 5 | L11: A | M11: A | N11: P | O11: P | P11: 5 | Q11: a | R11: A | S11: P | T11: P | U11: 5 | V11: a | W11: A | X11: a | Y11: a | Z11: 5 | AA11: =AVERAGE(K11,P11,U11,Z11) | AB11: =COUNTIF(G11:Z11,"P") | AC11: =COUNTIF(G11:Z11,"L") | AD11: =COUNTIF(G11:Z11,"A") | AE11: =AB11+AC11 | AF11: =AE11/16*10 | AG11: =AA11 | AH11: 18
B12: 4 | C12: 4 | D12: حياة ناصر جمعه راشد الكعبي | E12: NA | F12: NA | K12: 0 | P12: 0 | U12: 0 | Z12: 0 | AA12: =AVERAGE(K12,P12,U12,Z12) | AB12: =COUNTIF(G12:Z12,"P") | AC12: =COUNTIF(G12:Z12,"L") | AD12: =COUNTIF(G12:Z12,"A") | AE12: =AB12+AC12 | AF12: =AE12/16*10 | AG12: =AA12 | AH12: 18
B13: 5 | C13: 5 | D13: خالد ياسر احمد حسان على | E13: NA | F13: NA | K13: 0 | P13: 0 | U13: 0 | Z13: 0 | AA13: =AVERAGE(K13,P13,U13,Z13) | AB13: =COUNTIF(G13:Z13,"P") | AC13: =COUNTIF(G13:Z13,"L") | AD13: =COUNTIF(G13:Z13,"A") | AE13: =AB13+AC13 | AF13: =AE13/16*10 | AG13: =AA13 | AH13: 20
B14: 6 | C14: 6 | D14: زايد حمدان محمد ناجى احمد | E14: NA | F14: NA | K14: 0 | P14: 0 | U14: 0 | Z14: 0 | AA14: =AVERAGE(K14,P14,U14,Z14) | AB14: =COUNTIF(G14:Z14,"P") | AC14: =COUNTIF(G14:Z14,"L") | AD14: =COUNTIF(G14:Z14,"A") | AE14: =AB14+AC14 | AF14: =AE14/16*10 | AG14: =AA14 | AH14: 18
B15: 7 | C15: 7 | D15: سالم سليمان على محمد الكربي | E15: NA | F15: NA | K15: 0 | P15: 0 | U15: 0 | Z15: 0 | AA15: =AVERAGE(K15,P15,U15,Z15) | AB15: =COUNTIF(G15:Z15,"P") | AC15: =COUNTIF(G15:Z15,"L") | AD15: =COUNTIF(G15:Z15,"A") | AE15: =AB15+AC15 | AF15: =AE15/16*10 | AG15: =AA15 | AH15: 19
B16: 8 | C16: 8 | D16: سعيد سالم عبدالله محمد الكعبي | E16: NA | F16: NA | K16: 0 | P16: 0 | U16: 0 | Z16: 0 | AA16: =AVERAGE(K16,P16,U16,Z16) | AB16: =COUNTIF(G16:Z16,"P") | AC16: =COUNTIF(G16:Z16,"L") | AD16: =COUNTIF(G16:Z16,"A") | AE16: =AB16+AC16 | AF16: =AE16/16*10 | AG16: =AA16 | AH16: 19
B17: 9 | C17: 9 | D17: سلطان بن صالح بن عبدالله بن احمد البريكي | E17: NA | F17: NA | K17: 0 | P17: 0 | U17: 0 | Z17: 0 | AA17: =AVERAGE(K17,P17,U17,Z17) | AB17: =COUNTIF(G17:Z17,"P") | AC17: =COUNTIF(G17:Z17,"L") | AD17: =COUNTIF(G17:Z17,"A") | AE17: =AB17+AC17 | AF17: =AE17/16*10 | AG17: =AA17 | AH17: 20
B18: 10 | C18: 10 | D18: سلمان سالم احمد سالم المنصوري | E18: NA | F18: NA | K18: 0 | P18: 0 | U18: 0 | Z18: 0 | AA18: =AVERAGE(K18,P18,U18,Z18) | AB18: =COUNTIF(G18:Z18,"P") | AC18: =COUNTIF(G18:Z18,"L") | AD18: =COUNTIF(G18:Z18,"A") | AE18: =AB18+AC18 | AF18: =AE18/16*10 | AG18: =AA18 | AH18: 18
B19: 11 | C19: 11 | D19: شمسه عمران محمد شيبان المهيري | E19: NA | F19: NA | K19: 0 | P19: 0 | U19: 0 | Z19: 0 | AA19: =AVERAGE(K19,P19,U19,Z19) | AB19: =COUNTIF(G19:Z19,"P") | AC19: =COUNTIF(G19:Z19,"L") | AD19: =COUNTIF(G19:Z19,"A") | AE19: =AB19+AC19 | AF19: =AE19/16*10 | AG19: =AA19 | AH19: 18
B20: 12 | C20: 12 | D20: شيخة هداف رضوان عيضة المنهالي | E20: NA | F20: NA | K20: 0 | P20: 0 | U20: 0 | Z20: 0 | AA20: =AVERAGE(K20,P20,U20,Z20) | AB20: =COUNTIF(G20:Z20,"P") | AC20: =COUNTIF(G20:Z20,"L") | AD20: =COUNTIF(G20:Z20,"A") | AE20: =AB20+AC20 | AF20: =AE20/16*10 | AG20: =AA20 | AH20: 18
B21: 13 | C21: 13 | D21: عبدالرحمن سعيد محمد سالم الساعدي | E21: NA | F21: NA | K21: 0 | P21: 0 | U21: 0 | Z21: 0 | AA21: =AVERAGE(K21,P21,U21,Z21) | AB21: =COUNTIF(G21:Z21,"P") | AC21: =COUNTIF(G21:Z21,"L") | AD21: =COUNTIF(G21:Z21,"A") | AE21: =AB21+AC21 | AF21: =AE21/16*10 | AG21: =AA21 | AH21: 19
B22: 14 | C22: 14 | D22: عبدالله بدر حسين عيسى | E22: NA | F22: NA | K22: 0 | P22: 0 | U22: 0 | Z22: 0 | AA22: =AVERAGE(K22,P22,U22,Z22) | AB22: =COUNTIF(G22:Z22,"P") | AC22: =COUNTIF(G22:Z22,"L") | AD22: =COUNTIF(G22:Z22,"A") | AE22: =AB22+AC22 | AF22: =AE22/16*10 | AG22: =AA22 | AH22: 19
B23: 15 | C23: 15 | D23: عمر بن أحمد بن محمد بن مبروك الدهماني | E23: NA | F23: NA | K23: 0 | P23: 0 | U23: 0 | Z23: 0 | AA23: =AVERAGE(K23,P23,U23,Z23) | AB23: =COUNTIF(G23:Z23,"P") | AC23: =COUNTIF(G23:Z23,"L") | AD23: =COUNTIF(G23:Z23,"A") | AE23: =AB23+AC23 | AF23: =AE23/16*10 | AG23: =AA23 | AH23: 18
... B34: 26 | C34: 26 | D34: يوسف حمد على نصر ال صلاح | E34: NA | F34: NA | K34: 0 | P34: 0 | U34: 0 | Z34: 0 | AA34: =AVERAGE(K34,P34,U34,Z34) | AB34: =COUNTIF(G34:Z34,"P") | AC34: =COUNTIF(G34:Z34,"L") | AD34: =COUNTIF(G34:Z34,"A") | AE34: =AB34+AC34 | AF34: =AE34/16*10 | AG34: =AA34 | AH34: 20
B35: 27 | E35: NA | F35: NA | K35: 0 | P35: 0 | U35: 0 | Z35: 0 | AA35: =AVERAGE(K35,P35,U35,Z35) | AB35: =COUNTIF(G35:Z35,"P") | AC35: =COUNTIF(G35:Z35,"L") | AD35: =COUNTIF(G35:Z35,"A") | AE35: =AB35+AC35 | AF35: =AE35/16*10 | AG35: =AA35
B36: 28 | E36: NA | F36: NA | K36: 5 | L36: p | M36: p | N36: p | O36: p | P36: 5 | Q36: p | R36: p | S36: p | T36: p | U36: 5 | V36: a | W36: a | X36: a | Y36: a | Z36: 5 | AA36: =AVERAGE(K36,P36,U36,Z36) | AB36: =COUNTIF(G36:Z36,"P") | AC36: =COUNTIF(G36:Z36,"L") | AD36: =COUNTIF(G36:Z36,"A") | AE36: =AB36+AC36 | AF36: =AE36/16*10 | AG36: =AA36
B37: 29 | E37: NA | F37: NA | K37: 0 | P37: 0 | U37: 0 | Z37: 0 | AA37: =AVERAGE(K37,P37,U37,Z37) | AB37: =COUNTIF(G37:Z37,"P") | AC37: =COUNTIF(G37:Z37,"L") | AD37: =COUNTIF(G37:Z37,"A") | AE37: =AB37+AC37 | AF37: =AE37/16*10 | AG37: =AA37
B38: 30 | E38: NA | F38: NA | K38: 0 | P38: 0 | U38: 0 | Z38: 0 | AA38: =AVERAGE(K38,P38,U38,Z38) | AB38: =COUNTIF(G38:Z38,"P") | AC38: =COUNTIF(G38:Z38,"L") | AD38: =COUNTIF(G38:Z38,"A") | AE38: =AB38+AC38 | AF38: =AE38/16*10 | AG38: =AA38
B39: 31 | E39: NA | F39: NA | K39: 0 | P39: 0 | U39: 0 | Z39: 0 | AA39: =AVERAGE(K39,P39,U39,Z39) | AB39: =COUNTIF(G39:Z39,"P") | AC39: =COUNTIF(G39:Z39,"L") | AD39: =COUNTIF(G39:Z39,"A") | AE39: =AB39+AC39 | AF39: =AE39/16*10 | AG39: =AA39
B40: 32 | E40: NA | F40: NA | K40: 0 | P40: 0 | U40: 0 | Z40: 0 | AA40: =AVERAGE(K40,P40,U40,Z40) | AB40: =COUNTIF(G40:Z40,"P") | AC40: =COUNTIF(G40:Z40,"L") | AD40: =COUNTIF(G40:Z40,"A") | AE40: =AB40+AC40 | AF40: =AE40/16*10 | AG40: =AA40
B41: 33 | E41: NA | F41: NA | K41: 0 | P41: 0 | U41: 0 | Z41: 0 | AA41: =AVERAGE(K41,P41,U41,Z41) | AB41: =COUNTIF(G41:Z41,"P") | AC41: =COUNTIF(G41:Z41,"L") | AD41: =COUNTIF(G41:Z41,"A") | AE41: =AB41+AC41 | AF41: =AE41/16*10 | AG41: =AA41
B42: 34 | E42: NA | F42: NA | K42: 0 | P42: 0 | U42: 0 | Z42: 0 | AA42: =AVERAGE(K42,P42,U42,Z42) | AB42: =COUNTIF(G42:Z42,"P") | AC42: =COUNTIF(G42:Z42,"L") | AD42: =COUNTIF(G42:Z42,"A") | AE42: =AB42+AC42 | AF42: =AE42/16*10 | AG42: =AA42
B43: 35 | E43: NA | F43: NA | K43: 0 | P43: 0 | U43: 0 | Z43: 0 | AA43: =AVERAGE(K43,P43,U43,Z43) | AB43: =COUNTIF(G43:Z43,"P") | AC43: =COUNTIF(G43:Z43,"L") | AD43: =COUNTIF(G43:Z43,"A") | AE43: =AB43+AC43 | AF43: =AE43/16*10 | AG43: =AA43
B44: 36 | E44: NA | F44: NA | K44: 0 | P44: 0 | U44: 0 | Z44: 0 | AA44: =AVERAGE(K44,P44,U44,Z44) | AB44: =COUNTIF(G44:Z44,"P") | AC44: =COUNTIF(G44:Z44,"L") | AD44: =COUNTIF(G44:Z44,"A") | AE44: =AB44+AC44 | AF44: =AE44/16*10 | AG44: =AA44
B45: 37 | E45: NA | F45: NA | K45: 0 | P45: 0 | U45: 0 | Z45: 0 | AA45: =AVERAGE(K45,P45,U45,Z45) | AB45: =COUNTIF(G45:Z45,"P") | AC45: =COUNTIF(G45:Z45,"L") | AD45: =COUNTIF(G45:Z45,"A") | AE45: =AB45+AC45 | AF45: =AE45/16*10 | AG45: =AA45
B46: 38 | E46: NA | F46: NA | K46: 0 | P46: 0 | U46: 0 | Z46: 0 | AA46: =AVERAGE(K46,P46,U46,Z46) | AB46: =COUNTIF(G46:Z46,"P") | AC46: =COUNTIF(G46:Z46,"L") | AD46: =COUNTIF(G46:Z46,"A") | AE46: =AB46+AC46 | AF46: =AE46/16*10 | AG46: =AA46
B47: 39 | E47: NA | F47: NA | K47: 0 | P47: 0 | U47: 0 | Z47: 0 | AA47: =AVERAGE(K47,P47,U47,Z47) | AB47: =COUNTIF(G47:Z47,"P") | AC47: =COUNTIF(G47:Z47,"L") | AD47: =COUNTIF(G47:Z47,"A") | AE47: =AB47+AC47 | AF47: =AE47/16*10 | AG47: =AA47
B48: 40 | E48: NA | F48: NA | K48: 0 | P48: 0 | U48: 0 | Z48: 0 | AA48: =AVERAGE(K48,P48,U48,Z48) | AB48: =COUNTIF(G48:Z48,"P") | AC48: =COUNTIF(G48:Z48,"L") | AD48: =COUNTIF(G48:Z48,"A") | AE48: =AB48+AC48 | AF48: =AE48/16*10 | AG48: =AA48
... B58: 50 | E58: NA | F58: NA | K58: 0 | P58: 0 | U58: 0 | Z58: 0 | AA58: =AVERAGE(K58,P58,U58,Z58) | AB58: =COUNTIF(G58:Z58,"P") | AC58: =COUNTIF(G58:Z58,"L") | AD58: =COUNTIF(G58:Z58,"A") | AE58: =AB58+AC58 | AF58: =AE58/16*10 | AG58: =AA58

Sheet 4C - Marks
C1: Section: | D1: 4C | E1: Marks Recording Sheet
A2: Teacher Name: | D2: ='G4- Attendance'!D2 | E2: ='G4- Attendance'!E2
A3: School ID: | D3: ='G4- Attendance'!D3 | E3: ='G4- Attendance'!E3
A4: School Name: | D4: ='G4- Attendance'!D4 | E4: ='G4- Attendance'!E4
A5: Emirate/Area: | D5: ='G4- Attendance'!D5
A6: Council: | D6: ='G4- Attendance'!D6
E7: School-based Assessment (SB1) | F7: Attendance/ Effort | G7: School-based Total | H7: End of Term Total
B8: No | C8: Student # | D8: Student Name | E8: 80 marks | F8: 20 marks | G8: 100 marks | H8: 100 marks
B9: 1 | C9: 1 | D9: حصه صالح سالم البرك العامري | E9: 80 | F9: 18 | G9: 98 | H9: 99
